<?xml version="1.0" ?>

<robot name="robokoko_bot" xmlns:xacro="http://www.ros.org/wiki/xacro">

  <xacro:include filename="$(find slam_project)/urdf/robokoko_scratch.gazebo" />

	<!-- Link robot footprint --> 
  <link name="robot_footprint"/>

	<!-- Link chassis --> 
  <link name="chassis_link">

		<visual>
      <geometry>
      	<cylinder length="0.05" radius="0.15"/>
      </geometry>
    </visual>

    <collision name="collision">
      <geometry>
      	<cylinder length="0.05" radius="0.15"/>
      </geometry>
    </collision>

    <inertial>
      <mass value="2.0"/>
      <inertia 	ixx="0.011666666666666665" ixy="0" ixz="0" 
								iyy="0.011666666666666665" iyz="0"
						 		izz="0.0225"/>
    </inertial>

  </link>

	<!-- Link Front Caster --> 
	<link name='front_caster_link'>

		<visual>
		  <geometry>
				<sphere radius="0.0375"/>
		  </geometry>
		</visual>

		<collision name='front_caster_collision'>
		  <geometry>
				<sphere radius="0.0375"/>
		  </geometry>
		</collision>

		<inertial>
			<mass value=".100"/>
			<inertia
			  ixx="5.6250000000000005e-05" ixy="0" ixz="0"
			  iyy="5.6250000000000005e-05" iyz="0"
			  izz="5.6250000000000005e-05"
			/>
		</inertial>

	</link>

	<!-- Link Back Caster --> 
	<link name='back_caster_link'>

		<visual>
		  <geometry>
				<sphere radius="0.0375"/>
		  </geometry>
		</visual>

		<collision name='back_caster_collision'>
		  <geometry>
				<sphere radius="0.0375"/>
		  </geometry>
		</collision>

		<inertial>
			<mass value=".100"/>
			<inertia
			  ixx="5.6250000000000005e-05" ixy="0" ixz="0"
			  iyy="5.6250000000000005e-05" iyz="0"
			  izz="5.6250000000000005e-05"
			/>
		</inertial>

	</link>

	<!-- Link Left Wheel --> 
	<link name='left_wheel_link'>

		<visual>
			<origin xyz="0.0 0 0" rpy="0 1.5707 1.5707"/>
			<geometry>
				<cylinder radius="0.075" length="0.05"/>
			</geometry>
		</visual>

		<collision name='collision'>
			<origin xyz="0.0 0 0" rpy="0 1.5707 1.5707"/>
			<geometry>
				<cylinder radius="0.075" length="0.05"/>
			</geometry>
		</collision>

		<inertial>
			<mass value="1"/>
			<origin xyz="0.0 0 0" rpy="0 1.5707 1.5707"/>
				<inertia
			  ixx="0.0016145833333333329" ixy="0" ixz="0"
			  iyy="0.0016145833333333329" iyz="0"
			  izz="0.0028125"/>
		</inertial>

	</link>

	<!-- Link Right Wheel --> 
	<link name='right_wheel_link'>

		<visual>
			<origin xyz="0.0 0 0" rpy="0 1.5707 1.5707"/>
			<geometry>
				<cylinder radius="0.075" length="0.05"/>
			</geometry>
		</visual>

		<collision name='collision'>
			<origin xyz="0.0 0 0" rpy="0 1.5707 1.5707"/>
			<geometry>
				<cylinder radius="0.075" length="0.05"/>
			</geometry>
		</collision>

		<inertial>
			<mass value="1"/>
			<origin xyz="0.0 0 0" rpy="0 1.5707 1.5707"/>
				<inertia
			  ixx="0.0016145833333333329" ixy="0" ixz="0"
			  iyy="0.0016145833333333329" iyz="0"
			  izz="0.0028125"/>
		</inertial>

	</link>

	<!-- Link Body --> 
	<link name='body_link'>

		<visual>
		  <geometry>
				<cylinder length="0.4" radius="0.05"/>
		  </geometry>
		</visual>

		<collision name='body_collision'>
		  <geometry>
				<cylinder length="0.4" radius="0.05"/>
		  </geometry>
		</collision>

		<inertial>
			<mass value="0.1"/>
			<inertia
			  ixx="8.333333333333334e-05" ixy="0" ixz="0"
			  iyy="8.333333333333334e-05" iyz="0"
			  izz="0.00012500000000000003"
			/>
		</inertial>

	</link>

	<!-- Link Camera --> 
	<link name='camera_link'>

		<visual>
			<geometry>
				<box size="0.0125 0.125 0.0125"/>
			</geometry>
		</visual>

		<collision name='collision'>
			<geometry>
				<box size="0.0125 0.125 0.0125"/>
			</geometry>
		</collision>

		<inertial>
			<mass value="0.05"/>
			<inertia
			  ixx="1e-6" ixy="0" ixz="0"
			  iyy="1e-6" iyz="0"
			  izz="1e-6"
			/>
		</inertial>

	</link>

	<!-- Link RGB-D  --> 
	<link name='camera_rgbd_frame'></link>

	<link name='imu_link'></link>

	<!-- Link Lidar  --> 
	<link name='hokuyo'>

		<visual>
			<geometry>
				<mesh filename="package://slam_project/meshes/hokuyo.dae"/>	
			</geometry>
		</visual>

		<collision name='collision'>
			<geometry>
				<box size="0.05 0.05 0.05"/>
			</geometry>
		</collision>

		<inertial>
			<mass value="0.05"/>
			<inertia
			  ixx="1e-6" ixy="0" ixz="0"
			  iyy="1e-6" iyz="0"
			  izz="1e-6"
			/>
		</inertial>

	</link>

	<!-- Joint Robot footprint  --> 
  <joint name="robot_footprint_joint" type="fixed">
	  <origin xyz="0 0 0.075" rpy="0 0 0" />
    <parent link="robot_footprint"/>
    <child link="chassis_link"/>
  </joint>

	<!-- Joint left wheel  --> 
	<joint name="left_wheel_joint" type="continuous" >
		<origin xyz="0 0.175 0" rpy="0 0 0"/>
		<axis xyz="0 1 0">
			<dynamics>
				<damping>1.0</damping>
				<friction>1.0</friction>
			</dynamics>
		</axis>
		<limit effort="10000" velocity="1000"/>
		<parent link="chassis_link"/>
		<child link="left_wheel_link"/>
	</joint>

	<!-- Joint right wheel  --> 
	<joint name="right_wheel_joint" type="continuous" >
    <origin xyz="0 -0.175 0" rpy="0 0 0"/>
		<axis xyz="0 1 0">
			<dynamics>
				<damping>1.0</damping>
				<friction>1.0</friction>
			</dynamics>
		</axis>
		<limit effort="10000" velocity="1000"/>
		<parent link="chassis_link"/>
		<child link="right_wheel_link"/>
	</joint>

	<!-- Joint front caster  --> 
	<joint name="front_caster_joint" type="fixed" >
		<origin xyz="0.11 0 -0.0375" rpy="0 0 0"/>
		<parent link="chassis_link"/>
		<child link="front_caster_link"/>
	</joint>

	<!-- Joint back caster  --> 
	<joint name="back_caster_joint" type="fixed" >
		<origin xyz="-0.11 0 -0.0375" rpy="0 0 0"/>
		<parent link="chassis_link"/>
		<child link="back_caster_link"/>
	</joint>

	<!-- Joint body  --> 
	<joint name="body_joint" type="fixed" >
		<origin xyz="-0.015 0 0.225" rpy="0 0 0"/>
		<parent link="chassis_link"/>
		<child link="body_link"/>
	</joint>

	<!-- Joint lidar  --> 
	<joint name="lidar_joint" type="fixed" >
    <origin xyz="0 0 0.2175" rpy="0 0 0"/>
		<parent link="body_link"/>
		<child link="hokuyo"/>
	</joint>

	<!-- Joint camera  --> 
	<joint name="camera_joint" type="fixed" >
    <origin xyz="0.055 0 0.1" rpy="0 0 0"/>
		<parent link="body_link"/>
		<child link="camera_link"/>
	</joint>

	<!-- Joint camera rgbd  --> 
	<joint name="camera_rgbd_joint" type="fixed" >
		<parent link="camera_link"/>
		<child link="camera_rgbd_frame"/>
		<origin xyz="0 0 0" rpy="-1.57 0 -1.57"/>
	</joint>

	<!-- Joint Imu  --> 
	<joint name="imu_joint" type="fixed" >
		<parent link="body_link"/>
		<child link="imu_link"/>
		<origin xyz="0 0 0" rpy="0 0 0"/>
	</joint>

</robot>

