<?xml version='1.0'?>

<robot name="udacity_bot" xmlns:xacro="http://www.ros.org/wiki/xacro">

  <xacro:include filename="$(find slam_project)/urdf/udacity_bot.gazebo" />

  <link name="robot_footprint"></link>

  <joint name="robot_footprint_joint" type="fixed">
    <origin xyz="0 0 0" rpy="0 0 0" />
    <parent link="robot_footprint"/>
    <child link="chassis" />
  </joint>

  <link name='chassis'>

		<pose>0 0 0.1 0 0 0</pose>

		<inertial>
			<mass value="15.0"/>
			<origin xyz="0.0 0 0" rpy=" 0 0 0"/>
			<inertia
			  ixx="0.0625" ixy="0" ixz="0"
			  iyy="0.212" iyz="0"
			  izz="0.25"
			/>
		</inertial>

		<collision name='collision'>
			<origin xyz="0 0 0" rpy=" 0 0 0"/> 
			<geometry>
				<box size=".4 .2 .1"/>
			</geometry>
		</collision>

		<visual name='chassis_visual'>
			<origin xyz="0 0 0" rpy=" 0 0 0"/>
			<geometry>
				<box size=".4 .2 .1"/>
			</geometry>
		</visual>


  	</link>

	<joint name="left_wheel_hinge" type="continuous" >
		<parent link="chassis"/>
		<child link="left_wheel"/>
		<axis xyz="0 1 0" rpy="0 0 0">
			<dynamics>
				<damping>1.0</damping>
				<friction>1.0</friction>
			</dynamics>
		</axis>
		<origin xyz="0 0.15 0" rpy="0 0 0"/>
        <limit effort="10000" velocity="1000"/>
	</joint>

	<link name='left_wheel'>

		<inertial>
			<mass value="5.0"/>
			<origin xyz="0.0 0 0" rpy="0 1.5707 1.5707"/>
			<inertia
			  ixx="0.0135" ixy="0" ixz="0"
			  iyy="0.0135" iyz="0"
			  izz="0.025"
			/>
		</inertial>

		<collision name='collision'>
			<origin xyz="0.0 0 0" rpy="0 1.5707 1.5707"/>
			<geometry>
				<cylinder radius="0.1" length="0.05"/>
			</geometry>
		</collision>

		<visual name='left_wheel_visual'>
			<origin xyz="0.0 0 0" rpy="0 1.5707 1.5707"/>
			<geometry>
				<cylinder radius="0.1" length="0.05"/>
			</geometry>
		</visual>

	</link>

	<joint name="right_wheel_hinge" type="continuous" >
		<parent link="chassis"/>
		<child link="right_wheel"/>
		<axis xyz="0 1 0" rpy="0 0 0">
			<dynamics>
				<damping>1.0</damping>
				<friction>1.0</friction>
			</dynamics>
		</axis>
		<origin xyz="0 -0.15 0" rpy="0 0 0"/>
		<limit effort="10000" velocity="1000"/>
	</joint>

	<link name='right_wheel'>

		<inertial>
			<mass value="5.0"/>
			<origin xyz="0.0 0 0" rpy="0 1.5707 1.5707"/>
			<inertia
			  ixx="0.0135" ixy="0" ixz="0"
			  iyy="0.0135" iyz="0"
			  izz="0.025"
			/>
		</inertial>

		<collision name='collision'>
			<origin xyz="0.0 0 0" rpy="0 1.5707 1.5707"/>
			<geometry>
				<cylinder radius="0.1" length="0.05"/>
			</geometry>
		</collision>

		<visual name='right_wheel_visual'>
			<origin xyz="0.0 0 0" rpy="0 1.5707 1.5707"/>
			<geometry>
				<cylinder radius="0.1" length="0.05"/>
			</geometry>
		</visual>

	</link>

	<joint name="camera_joint" type="fixed" >
		<parent link="chassis"/>
		<child link="camera_link"/>
		<origin xyz="0.2 0 0" rpy="0 0 0"/>
	</joint>

	<link name='camera_link'>

		<inertial>
			<mass value="0.1"/>
			<origin xyz="0.0 0 0" rpy="0.0 0 0"/>
			<inertia
			  ixx="1e-6" ixy="0" ixz="0"
			  iyy="1e-6" iyz="0"
			  izz="1e-6"
			/>
		</inertial>

		<collision name='collision'>
			<origin xyz="0.0 0 0" rpy="0 0 0"/>
			<geometry>
				<box size="0.05 0.05 0.05"/>
			</geometry>
		</collision>

		<visual name='camera_visual'>
			<origin xyz="0.0 0 0" rpy="0 0 0"/>
			<geometry>
				<box size="0.05 0.05 0.05"/>
			</geometry>
		</visual>

	</link>

	<link name='camera_rgbd_frame'></link>

	<joint name="camera_rgbd_joint" type="fixed" >
		<parent link="camera_link"/>
		<child link="camera_rgbd_frame"/>
		<origin xyz="0 0 0" rpy="-1.57 0 -1.57"/>
	</joint>

	<joint name="hokuyo_joint" type="fixed" >
		<parent link="chassis"/>
		<child link="hokuyo"/>
		<origin xyz="0.15 0 0.1" rpy="0 0 0"/>
	</joint>


	<link name='hokuyo'>

		<inertial>
			<mass value="0.1"/>
			<origin xyz="0.0 0 0" rpy="0 0 0"/>
			<inertia
			  ixx="1e-6" ixy="0" ixz="0"
			  iyy="1e-6" iyz="0"
			  izz="1e-6"
			/>
		</inertial>

		<collision name='collision'>
			<origin xyz="0.0 0 0" rpy="0 0 0"/>
			<geometry>
				<box size="0.1 0.1 0.1"/>
			</geometry>
		</collision>

		<visual name='camera_visual'>
			<origin xyz="0.0 0 0" rpy="0 0 0"/>
			<geometry>
				<mesh filename="package://slam_project/meshes/hokuyo.dae"/>	
			</geometry>
		</visual>

	</link>

	<joint name="back_caster_joint" type="fixed" >
		<parent link="chassis"/>
		<child link="back_caster"/>
		<origin xyz="0 0 0" rpy="0 0 0"/>
	</joint>

	<link name='back_caster'>

		<inertial>
			<mass value="0.1"/>
			<origin xyz="0.0 0 0" rpy="0 0 0"/>
			<inertia
			  ixx="1e-6" ixy="0" ixz="0"
			  iyy="1e-6" iyz="0"
			  izz="1e-6"
			/>
		</inertial>

		<collision name='back_caster_collision'>
			<origin xyz="-0.15 0 -0.05" rpy=" 0 0 0"/>
			<geometry>
				<sphere radius="0.05"/>
			</geometry>
		</collision>

		<visual name='back_caster_visual'>
		  <origin xyz="-0.15 0 -0.05" rpy=" 0 0 0"/>
		  <geometry>
			<sphere radius="0.05"/>
		  </geometry>
		</visual>

	</link>

	<joint name="front_caster_joint" type="fixed" >
		<parent link="chassis"/>
		<child link="front_caster"/>
		<origin xyz="0 0 0" rpy="0 0 0"/>
	</joint>

	<link name='front_caster'>

		<inertial>
			<mass value="0.1"/>
			<origin xyz="0.0 0 0" rpy="0 0 0"/>
			<inertia
			  ixx="1e-6" ixy="0" ixz="0"
			  iyy="1e-6" iyz="0"
			  izz="1e-6"
			/>
		</inertial>

		<collision name='front_caster_collision'>
		  <origin xyz="0.15 0 -0.05" rpy=" 0 0 0"/>
		  <geometry>
			<sphere radius="0.05"/>
		  </geometry>
		</collision>

		<visual name='front_caster_visual'>
		  <origin xyz="0.15 0 -0.05" rpy=" 0 0 0"/>
		  <geometry>
			<sphere radius="0.05"/>
		  </geometry>
		</visual>

	</link>

</robot>

